// index.js
import { add } from './utils.js';

function start() {
    const sum = add(5, 10);
    console.log(`The sum is: ${sum}`);
}

start();

//Exercise 2.1 Event Loop
//Micro-task runs before macro-task
/*console.log('A: Script start');//1

fetch('https://v2.api.noroff.dev/old-games/1').then(function () {
  console.log('B: Promise resolved');//micro, 3
});

setTimeout(function () {
  console.log('C: setTimeout finished');//macro, 4
}, 0);

console.log('D: Script end');//2*/

//Example of creating a Resolving Promise

/*const successfulPromise = new Promise((resolve, reject) => {
  console.log('Executor function started. Waiting for the operation...');

  setTimeout(() => {
    // The operation was successful.
    const resultData = { userId: 1, username: 'testuser' };
    resolve(resultData);
  }, 2000);
});

console.log('Promise has been created.');

successfulPromise.then((data) => {
  console.log('Promise was fulfilled!');
  console.log('Received data:', data);
});*/

// Rejecting Promise

/*const conditionalPromise = new Promise((resolve, reject) => {
  setTimeout(() => {
    const isSuccess = Math.random() > 0.5; // 50% chance of failure

    if (isSuccess) {
      resolve('Operation was successful.');
    } else {
      reject(new Error('Operation failed! Could not connect.'));
    }
  }, 1500);
});

conditionalPromise
  .then((message) => {
    console.log('Success:', message);
  })
  .catch((error) => {
    console.error('Failure:', error.message);
  });*/

/*function checkAuthStatus() {
  return new Promise((resolve, reject) => {

    setTimeout(() => {
      const isLoggedIn = Math.random() > 0.2;

      if (isLoggedIn) {
        resolve(`{ success: true, message: 'User is authenticated.' }`);
      } else {
        reject(new Error('Authentication failed!'));
      }
    }, 1000);// delay goes inside the setTimeout
  });
} 

checkAuthStatus()
  .then((message) => {
    console.log('Success:', message);
  })
  .catch((error) => {
    console.log('Failure:', error.message);
  });*/


  //Exercise 2.1: Promise.all and Promise.allSettled
/*
This script demonstrates how to fetch and log data from two different API endpoints concurrently.
It uses async/await with Promise.all() to wait for both network requests to complete before
processing the responses.
*/

// Define the base URL for the API.
//const BASE_URL = 'https://v2.api.noroff.dev/old-games';

/**

Fetches game data for a given game ID from the Noroff API.

@param {number} gameId - The ID of the game to fetch.

@returns {Promise<object>} A promise that resolves with the parsed JSON data.
*/

/*const BASE_URL = 'https://v2.api.noroff.dev/old-games';
console.log(BASE_URL);

async function fetchGames() {
  console.log('Initiating current API calls...');

  try {
    const responses = await Promise.all([fetch(`${BASE_URL}/1`),
    fetch(`${BASE_URL}/2`)]);

   for (const response of responses) {
    if(!response.ok) {
      throw new Error(`HTTP error! status: ${response.status} from ${response.url}`);
      
    }
   }

   const games = await Promise.all(
    responses.map(response => response.json())
   );

   console.log('Fetching games was successful! Here is the data:')
   console.log(games);
  } catch (error) {
    console.log('At least one of the games could not be fetched from the API.', error);
  }

}
fetchGames();*/

const BASE_URL = 'https://v2.api.noroff.dev/old-games';
console.log(BASE_URL);

async function fetchGamesRobustly() {
  console.log('Initiating current API calls...');

  try {
    const responses = await Promise.allSettled([fetch(`${BASE_URL}/1`),
    fetch(`${BASE_URL}/9999`),
    fetch(`https://invalid.url.to.test.rejection`)
]);

   for (const result of responses) {
      if (result.status === 'fulfilled') {
        const response = result.value;
        if (response.ok) {
          // Process and log JSON for fulfilled and OK responses
          const gameData = await response.json();
          console.log(`ü§© Game data fetched successfully for: ${gameData.title}`);
          console.log(gameData);
        } else {
          // Log a warning for fulfilled but not-OK responses
          console.warn(`‚ö†Ô∏è Warning: Fetch was successful, but the response status was not ok: ${response.status} from ${response.url}`);
        }
      } else if (result.status === 'rejected') {
        // Log an error for rejected promises (e.g., network errors)
        console.error(`‚ùå Error: A network request failed. Reason:`, result.reason);
      }
    }
    console.log('All promises have settled. Check the logs above for individual results.');
  } catch (error) {
    // This catch block would only be reached if Promise.allSettled itself failed, which is rare
    console.error('An unexpected error occurred during the robust fetch process:', error);
  }
}

fetchGamesRobustly();